Workbook
Name \: #REF!
Name \: #REF!
Name \_JUNK: #N/A
Name \0: #N/A
Name \a: #REF!
Name \a: #REF!
Name \b: #REF!
Name \b: #REF!
Name \c: #REF!
Name \c: #REF!
Name \cac: #REF!
Name \d: #REF!
Name \da: #REF!
Name \dfhdtjht: #REF!
Name \e: #N/A
Name \f: #N/A
Name \fdfdr: #REF!
Name \fdfdr: #REF!
Name \FDWFDWF: #REF!
Name \FDWFDWF: #REF!
Name \g: #N/A
Name \h: #N/A
Name \hhh: #REF!
Name \hhh: #REF!
Name \I: #REF!
Name \I: #REF!
Name \iii: #REF!
Name \iii: #REF!
Name \J: #REF!
Name \K: #REF!
Name \ka: #REF!
Name \kkkk: #REF!
Name \l: #N/A
Name \lll: #REF!
Name \lll: #REF!
Name \M: #REF!
Name \M: #REF!
Name \ma: #REF!
Name \ma: #REF!
Name \N: #REF!
Name \na: #REF!
Name \O: #REF!
Name \p: #N/A
Name \pa: #REF!
Name \pa: #REF!
Name \par: #REF!
Name \par: #REF!
Name \pppp: #REF!
Name \pppp: #REF!
Name \Q: #N/A
Name \qa: #REF!
Name \qa: #REF!
Name \qaqa: #REF!
Name \qaqa: #REF!
Name \r: [69]MCMD95!$Q$121
Name \r: [70]MCMD95!$Q$121
Name \ra: #REF!
Name \ra: #REF!
Name \s: #N/A
Name \sasa: #REF!

Sheet ASSUMP.

Sheet Budget Plan
A1: PROJECT NAME | F1: Period | G1: 1 | H1: 2 | I1: 3 | J1: 4 | K1: 5 | L1: 6 | M1: 7 | N1: 8 | O1: 9 | P1: 10 | Q1: 11 | R1: 12 | S1: 13 | T1: 14 | U1: 15 | V1: 16 | W1: 17 | X1: 18 | Y1: 19 | Z1: 20 | AA1: 21 | AB1: 22 | AC1: 23 | AD1: 24 | AE1: 25 | AF1: 26 | AG1: 27 | AH1: 28 | AI1: 29 | AJ1: 30 | AK1: 31 | AL1: 32 | AM1: 33 | AN1: 34 | AO1: 35 | AP1: 36
F2: Year | G2: =YEAR(G3) -> 2019 | H2: =YEAR(H3) -> 2019 | I2: =YEAR(I3) -> 2019 | J2: =YEAR(J3) -> 2019 | K2: =YEAR(K3) -> 2019 | L2: =YEAR(L3) -> 2019 | M2: =YEAR(M3) -> 2019 | N2: =YEAR(N3) -> 2019 | ... AP2: =YEAR(AP3) -> 2022
F3: Month | G3: 43586 | H3: 43617 | I3: 43647 | J3: 43678 | K3: 43709 | L3: 43739 | M3: 43770 | N3: 43800 | O3: 43831 | P3: 43862 | Q3: 43891 | R3: 43922 | S3: 43952 | T3: 43983 | U3: 44013 | V3: 44044 | W3: 44075 | X3: 44105 | Y3: 44136 | Z3: 44166 | AA3: 44197 | AB3: 44228 | AC3: 44256 | AD3: 44287 | AE3: 44317 | AF3: 44348 | AG3: 44378 | AH3: 44409 | AI3: 44440 | AJ3: 44470 | AK3: 44501 | AL3: 44531 | AM3: 44562 | AN3: 44593 | AO3: 44621 | AP3: 44652
B4: YEAR 1 | C4: YEAR 2 | D4: YEAR 3 | E4: Assump. | AQ4: TOTAL | AR4: %
A5: Forecast
A6: PACKAGE A | F6: growth
A7: accumulate | G7: =G6 -> 0 | H7: =G7+H6 -> 0 | I7: =H7+I6 -> 0 | J7: =I7+J6 -> 0 | K7: =J7+K6 -> 0 | L7: =K7+L6 -> 0 | M7: =L7+M6 -> 0 | N7: =M7+N6 -> 0 | O7: =N7+O6 -> 0 | ... AP7: =AO7+AP6 -> 0
A8: PACKAGE B | F8: growth
A9: accumulate | G9: =G8 -> 0 | H9: =G9+H8 -> 0 | I9: =H9+I8 -> 0 | J9: =I9+J8 -> 0 | K9: =J9+K8 -> 0 | L9: =K9+L8 -> 0 | M9: =L9+M8 -> 0 | N9: =M9+N8 -> 0 | O9: =N9+O8 -> 0 | ... AP9: =AO9+AP8 -> 0
A10: PACKAGE C | F10: growth
A11: accumulate | G11: =G10 -> 0 | H11: =G11+H10 -> 0 | I11: =H11+I10 -> 0 | J11: =I11+J10 -> 0 | K11: =J11+K10 -> 0 | L11: =K11+L10 -> 0 | M11: =L11+M10 -> 0 | N11: =M11+N10 -> 0 | O11: =N11+O10 -> 0 | ... AP11: =AO11+AP10 -> 0
A19: P/L | AQ19: TOTAL | AR19: %
A20: Revenue | G20: =SUM(G21:G22) -> 0 | H20: =SUM(H21:H22) -> 0 | I20: =SUM(I21:I22) -> 0 | J20: =SUM(J21:J22) -> 0 | K20: =SUM(K21:K22) -> 0 | L20: =SUM(L21:L22) -> 0 | M20: =SUM(M21:M22) -> 0 | N20: =SUM(N21:N22) -> 0 | ... AP20: =SUM(AP21:AP22) -> 0 | AQ20: =SUM(G20:AP20) -> 0 | AR20: =AQ20/$AQ$20 -> #DIV/0!
A21: From INET (Develop Platform) | AQ21: =SUM(G21:AP21) -> 0 | AR21: =AQ21/$AQ$20 -> #DIV/0!
A22: Revenue From sales | G22: =SUM(G23:G27) -> 0 | H22: =SUM(H23:H27) -> 0 | I22: =SUM(I23:I27) -> 0 | J22: =SUM(J23:J27) -> 0 | K22: =SUM(K23:K27) -> 0 | L22: =SUM(L23:L27) -> 0 | M22: =SUM(M23:M27) -> 0 | N22: =SUM(N23:N27) -> 0 | ... AP22: =SUM(AP23:AP27) -> 0 | AQ22: =SUM(G22:AP22) -> 0 | AR22: =AQ22/$AQ$20 -> #DIV/0!
A23: PACKAGE A | F23: baht | G23: =$E$23*G7 -> 0 | H23: =$E$23*H7 -> 0 | I23: =$E$23*I7 -> 0 | J23: =$E$23*J7 -> 0 | K23: =$E$23*K7 -> 0 | L23: =$E$23*L7 -> 0 | M23: =$E$23*M7 -> 0 | N23: =$E$23*N7 -> 0 | ... AP23: =$E$23*AP7 -> 0 | AQ23: =SUM(G23:AP23) -> 0 | AR23: =AQ23/$AQ$20 -> #DIV/0!
A24: PACKAGE B | F24: baht | G24: =$E$24*G9 -> 0 | H24: =$E$24*H9 -> 0 | I24: =$E$24*I9 -> 0 | J24: =$E$24*J9 -> 0 | K24: =$E$24*K9 -> 0 | L24: =$E$24*L9 -> 0 | M24: =$E$24*M9 -> 0 | N24: =$E$24*N9 -> 0 | ... AP24: =$E$24*AP9 -> 0 | AQ24: =SUM(G24:AP24) -> 0 | AR24: =AQ24/$AQ$20 -> #DIV/0!
A25: PACKAGE C | F25: baht | G25: =$E$25*G11 -> 0 | H25: =$E$25*H11 -> 0 | I25: =$E$25*I11 -> 0 | J25: =$E$25*J11 -> 0 | K25: =$E$25*K11 -> 0 | L25: =$E$25*L11 -> 0 | M25: =$E$25*M11 -> 0 | N25: =$E$25*N11 -> 0 | ... AP25: =$E$25*AP11 -> 0 | AQ25: =SUM(G25:AP25) -> 0 | AR25: =AQ25/$AQ$20 -> #DIV/0!
AQ26: =SUM(G26:AP26) -> 0 | AR26: =AQ26/$AQ$20 -> #DIV/0!
AQ27: =SUM(G27:AP27) -> 0 | AR27: =AQ27/$AQ$20 -> #DIV/0!
A28: Direct Cost | G28: ='Infrastructure (Direct Cost)'!B31 -> 0 | H28: ='Infrastructure (Direct Cost)'!C31 -> 0 | I28: ='Infrastructure (Direct Cost)'!D31 -> 0 | J28: ='Infrastructure (Direct Cost)'!E31 -> 0 | K28: ='Infrastructure (Direct Cost)'!F31 -> 0 | L28: ='Infrastructure (Direct Cost)'!G31 -> 0 | M28: ='Infrastructure (Direct Cost)'!H31 -> 0 | N28: ='Infrastructure (Direct Cost)'!I31 -> 0 | ... R28: ='Infrastructure (Direct Cost)'!M31 -> 0 | S28: ='Infrastructure (Direct Cost)'!B32 -> 0 | T28: ='Infrastructure (Direct Cost)'!C32 -> 0 | U28: ='Infrastructure (Direct Cost)'!D32 -> 0 | V28: ='Infrastructure (Direct Cost)'!E32 -> 0 | W28: ='Infrastructure (Direct Cost)'!F32 -> 0 | X28: ='Infrastructure (Direct Cost)'!G32 -> 0 | Y28: ='Infrastructure (Direct Cost)'!H32 -> 0 | Z28: ='Infrastructure (Direct Cost)'!I32 -> 0 | ... AD28: ='Infrastructure (Direct Cost)'!M32 -> 0 | AE28: ='Infrastructure (Direct Cost)'!B33 -> 0 | AF28: ='Infrastructure (Direct Cost)'!C33 -> 0 | AG28: ='Infrastructure (Direct Cost)'!D33 -> 0 | AH28: ='Infrastructure (Direct Cost)'!E33 -> 0 | AI28: ='Infrastructure (Direct Cost)'!F33 -> 0 | AJ28: ='Infrastructure (Direct Cost)'!G33 -> 0 | AK28: ='Infrastructure (Direct Cost)'!H33 -> 0 | AL28: ='Infrastructure (Direct Cost)'!I33 -> 0 | ... AP28: ='Infrastructure (Direct Cost)'!M33 -> 0 | AQ28: =SUM(G28:AP28) -> 0 | AR28: =AQ28/$AQ$20 -> #DIV/0!
A29: Onetime | AQ29: =SUM(G29:AP29) -> 0 | AR29: =AQ29/$AQ$20 -> #DIV/0!
E30: Depreciation | F30: =5 -> 5 | AQ30: =SUM(G30:AP30) -> 0 | AR30: =AQ30/$AQ$20 -> #DIV/0!
E31: Depreciation | F31: =5 -> 5 | AQ31: =SUM(G31:AP31) -> 0 | AR31: =AQ31/$AQ$20 -> #DIV/0!
E32: Depreciation | F32: =5 -> 5 | AQ32: =SUM(G32:AP32) -> 0 | AR32: =AQ32/$AQ$20 -> #DIV/0!
E33: Depreciation | F33: =5 -> 5 | AQ33: =SUM(G33:AP33) -> 0 | AR33: =AQ33/$AQ$20 -> #DIV/0!
E34: Depreciation | F34: =5 -> 5 | AQ34: =SUM(G34:AP34) -> 0 | AR34: =AQ34/$AQ$20 -> #DIV/0!
E35: Depreciation | F35: =5 -> 5 | AQ35: =SUM(G35:AP35) -> 0 | AR35: =AQ35/$AQ$20 -> #DIV/0!
AQ36: =SUM(G36:AP36) -> 0 | AR36: =AQ36/$AQ$20 -> #DIV/0!
A37: Recurring | B37: Fix cost รายเดือน | AQ37: =SUM(G37:AP37) -> 0 | AR37: =AQ37/$AQ$20 -> #DIV/0!
A38: Cloud | AQ38: =SUM(G38:AP38) -> 0 | AR38: =AQ38/$AQ$20 -> #DIV/0!
AQ39: =SUM(G39:AP39) -> 0 | AR39: =AQ39/$AQ$20 -> #DIV/0!
AQ40: =SUM(G40:AP40) -> 0 | AR40: =AQ40/$AQ$20 -> #DIV/0!
AQ41: =SUM(G41:AP41) -> 0 | AR41: =AQ41/$AQ$20 -> #DIV/0!
A42: Pay Per Use | B42: ค่าใช้จ่ายผันแปร ตาม Forecast | AQ42: =SUM(G42:AP42) -> 0 | AR42: =AQ42/$AQ$20 -> #DIV/0!
AQ43: =SUM(G43:AP43) -> 0 | AR43: =AQ43/$AQ$20 -> #DIV/0!
AQ44: =SUM(G44:AP44) -> 0 | AR44: =AQ44/$AQ$20 -> #DIV/0!
AQ45: =SUM(G45:AP45) -> 0 | AR45: =AQ45/$AQ$20 -> #DIV/0!
A46: Operation | B46: เงินเดือน Engineer | G46: ='Developer (Direct Cost)'!C31 -> 0 | H46: ='Developer (Direct Cost)'!D31 -> 0 | I46: ='Developer (Direct Cost)'!E31 -> 0 | J46: ='Developer (Direct Cost)'!F31 -> 0 | K46: ='Developer (Direct Cost)'!G31 -> 0 | L46: ='Developer (Direct Cost)'!H31 -> 0 | M46: ='Developer (Direct Cost)'!I31 -> 0 | N46: ='Developer (Direct Cost)'!J31 -> 0 | ... R46: ='Developer (Direct Cost)'!N31 -> 0 | S46: ='Developer (Direct Cost)'!C32 -> 0 | T46: ='Developer (Direct Cost)'!D32 -> 0 | U46: ='Developer (Direct Cost)'!E32 -> 0 | V46: ='Developer (Direct Cost)'!F32 -> 0 | W46: ='Developer (Direct Cost)'!G32 -> 0 | X46: ='Developer (Direct Cost)'!H32 -> 0 | Y46: ='Developer (Direct Cost)'!I32 -> 0 | Z46: ='Developer (Direct Cost)'!J32 -> 0 | ... AD46: ='Developer (Direct Cost)'!N32 -> 0 | AE46: ='Infrastructure (Direct Cost)'!B33 -> 0 | AF46: ='Infrastructure (Direct Cost)'!C33 -> 0 | AG46: ='Infrastructure (Direct Cost)'!D33 -> 0 | AH46: ='Infrastructure (Direct Cost)'!E33 -> 0 | AI46: ='Infrastructure (Direct Cost)'!F33 -> 0 | AJ46: ='Infrastructure (Direct Cost)'!G33 -> 0 | AK46: ='Infrastructure (Direct Cost)'!H33 -> 0 | AL46: ='Infrastructure (Direct Cost)'!I33 -> 0 | ... AP46: ='Infrastructure (Direct Cost)'!M33 -> 0 | AQ46: =SUM(G46:AP46) -> 0 | AR46: =AQ46/$AQ$20 -> #DIV/0!
AQ47: =SUM(G47:AP47) -> 0 | AR47: =AQ47/$AQ$20 -> #DIV/0!
...

Sheet REVENUE
A1: Forecast & Revenue
A2: Year1
A3: CATEGORY | E3: 44197 | G3: 44228 | I3: 44256 | K3: 44287 | M3: 44317 | O3: 44348 | Q3: 44378 | S3: 44409 | U3: 44440 | W3: 44470 | Y3: 44501 | AA3: 44531 | AB3: Total
A5: Project
A6: Ads
A7: xxxx
A10: Design Project condo | B10: 26 | C10: 850 | D10: 0 | E10: =(B10*C10)*D10 -> 0 | F10: 0 | G10: =(B10*C10)*F10 -> 0 | H10: 0 | I10: =(B10*C10)*H10 -> 0 | J10: 0 | K10: =(B10*C10)*J10 -> 0 | L10: 0 | M10: =(B10*C10)*L10 -> 0 | N10: 0 | O10: =(B10*C10)*N10 -> 0 | P10: 10 | Q10: =(B10*C10)*P10 -> 221000 | R10: 10 | S10: =(B10*C10)*R10 -> 221000 | T10: 10 | U10: =(B10*C10)*T10 -> 221000 | V10: 10 | W10: =(B10*C10)*V10 -> 221000 | X10: 10 | Y10: =(B10*C10)*X10 -> 221000 | Z10: 10 | AA10: =(B10*C10)*Z10 -> 221000
A11: Design Project condo | B11: 33 | C11: 850 | D11: 0 | E11: =(B11*C11)*D11 -> 0 | F11: 0 | G11: =(B11*C11)*F11 -> 0 | H11: 0 | I11: =(B11*C11)*H11 -> 0 | J11: 0 | K11: =(B11*C11)*J11 -> 0 | L11: 0 | M11: =(B11*C11)*L11 -> 0 | N11: 0 | O11: =(B11*C11)*N11 -> 0 | P11: 5 | Q11: =(B11*C11)*P11 -> 140250 | R11: 5 | S11: =(B11*C11)*R11 -> 140250 | T11: 5 | U11: =(B11*C11)*T11 -> 140250 | V11: 5 | W11: =(B11*C11)*V11 -> 140250 | X11: 5 | Y11: =(B11*C11)*X11 -> 140250 | Z11: 5 | AA11: =(B11*C11)*Z11 -> 140250
A12: Design Project condo | B12: 64 | C12: 850 | D12: 0 | E12: =(B12*C12)*D12 -> 0 | F12: 0 | G12: =(B12*C12)*F12 -> 0 | H12: 0 | I12: =(B12*C12)*H12 -> 0 | J12: 0 | K12: =(B12*C12)*J12 -> 0 | L12: 0 | M12: =(B12*C12)*L12 -> 0 | N12: 0 | O12: =(B12*C12)*N12 -> 0 | P12: 2 | Q12: =(B12*C12)*P12 -> 108800 | R12: 2 | S12: =(B12*C12)*R12 -> 108800 | T12: 2 | U12: =(B12*C12)*T12 -> 108800 | V12: 2 | W12: =(B12*C12)*V12 -> 108800 | X12: 2 | Y12: =(B12*C12)*X12 -> 108800 | Z12: 2 | AA12: =(B12*C12)*Z12 -> 108800
A13: Design Project condo | B13: 100 | C13: 850 | D13: 0 | E13: =(B13*C13)*D13 -> 0 | F13: 0 | G13: =(B13*C13)*F13 -> 0 | H13: 0 | I13: =(B13*C13)*H13 -> 0 | J13: 0 | K13: =(B13*C13)*J13 -> 0 | L13: 0 | M13: =(B13*C13)*L13 -> 0 | N13: 0 | O13: =(B13*C13)*N13 -> 0 | P13: 0 | Q13: =(B13*C13)*P13 -> 0 | R13: 0 | S13: =(B13*C13)*R13 -> 0 | T13: 0 | U13: =(B13*C13)*T13 -> 0 | V13: 0 | W13: =(B13*C13)*V13 -> 0 | X13: 0 | Y13: =(B13*C13)*X13 -> 0 | Z13: 0 | AA13: =(B13*C13)*Z13 -> 0
K14: =(B14*C14)*J14 -> 0 | M14: =(B14*C14)*L14 -> 0 | O14: =(B14*C14)*N14 -> 0 | Q14: =(B14*C14)*P14 -> 0 | S14: =(B14*C14)*R14 -> 0 | U14: =(B14*C14)*T14 -> 0 | W14: =(B14*C14)*V14 -> 0 | Y14: =(B14*C14)*X14 -> 0 | AA14: =(B14*C14)*Z14 -> 0
A15: Design Project House | B15: 150 | C15: 850 | D15: 0 | E15: =(B15*C15)*D15 -> 0 | F15: 0 | G15: =(B15*C15)*F15 -> 0 | H15: 0 | I15: =(B15*C15)*H15 -> 0 | J15: 0 | K15: =(B15*C15)*J15 -> 0 | L15: 0 | M15: =(B15*C15)*L15 -> 0 | N15: 0 | O15: =(B15*C15)*N15 -> 0 | P15: 10 | Q15: =(B15*C15)*P15 -> 1275000 | R15: 10 | S15: =(B15*C15)*R15 -> 1275000 | T15: 10 | U15: =(B15*C15)*T15 -> 1275000 | V15: 10 | W15: =(B15*C15)*V15 -> 1275000 | X15: 10 | Y15: =(B15*C15)*X15 -> 1275000 | Z15: 10 | AA15: =(B15*C15)*Z15 -> 1275000
A16: Design Project House | B16: 250 | C16: 850 | D16: 0 | E16: =(B16*C16)*D16 -> 0 | F16: 0 | G16: =(B16*C16)*F16 -> 0 | H16: 0 | I16: =(B16*C16)*H16 -> 0 | J16: 0 | K16: =(B16*C16)*J16 -> 0 | L16: 0 | M16: =(B16*C16)*L16 -> 0 | N16: 0 | O16: =(B16*C16)*N16 -> 0 | P16: 5 | Q16: =(B16*C16)*P16 -> 1062500 | R16: 5 | S16: =(B16*C16)*R16 -> 1062500 | T16: 5 | U16: =(B16*C16)*T16 -> 1062500 | V16: 5 | W16: =(B16*C16)*V16 -> 1062500 | X16: 5 | Y16: =(B16*C16)*X16 -> 1062500 | Z16: 5 | AA16: =(B16*C16)*Z16 -> 1062500
A17: Design Project House | B17: 350 | C17: 850 | D17: 0 | E17: =(B17*C17)*D17 -> 0 | F17: 0 | G17: =(B17*C17)*F17 -> 0 | H17: 0 | I17: =(B17*C17)*H17 -> 0 | J17: 0 | K17: =(B17*C17)*J17 -> 0 | L17: 0 | M17: =(B17*C17)*L17 -> 0 | N17: 0 | O17: =(B17*C17)*N17 -> 0 | P17: 2 | Q17: =(B17*C17)*P17 -> 595000 | R17: 2 | S17: =(B17*C17)*R17 -> 595000 | T17: 2 | U17: =(B17*C17)*T17 -> 595000 | V17: 2 | W17: =(B17*C17)*V17 -> 595000 | X17: 2 | Y17: =(B17*C17)*X17 -> 595000 | Z17: 2 | AA17: =(B17*C17)*Z17 -> 595000
A18: Design Project House | B18: 500 | C18: 850 | D18: 0 | E18: =(B18*C18)*D18 -> 0 | F18: 0 | G18: =(B18*C18)*F18 -> 0 | H18: 0 | I18: =(B18*C18)*H18 -> 0 | J18: 0 | K18: =(B18*C18)*J18 -> 0 | L18: 0 | M18: =(B18*C18)*L18 -> 0 | N18: 0 | O18: =(B18*C18)*N18 -> 0 | P18: 0 | Q18: =(B18*C18)*P18 -> 0 | R18: 0 | S18: =(B18*C18)*R18 -> 0 | T18: 0 | U18: =(B18*C18)*T18 -> 0 | V18: 0 | W18: =(B18*C18)*V18 -> 0 | X18: 0 | Y18: =(B18*C18)*X18 -> 0 | Z18: 0 | AA18: =(B18*C18)*Z18 -> 0
K19: =(B19*C19)*J19 -> 0 | M19: =(B19*C19)*L19 -> 0 | O19: =(B19*C19)*N19 -> 0 | Q19: =(B19*C19)*P19 -> 0 | S19: =(B19*C19)*R19 -> 0 | U19: =(B19*C19)*T19 -> 0 | W19: =(B19*C19)*V19 -> 0 | Y19: =(B19*C19)*X19 -> 0 | AA19: =(B19*C19)*Z19 -> 0
A20: Design Project Shop | B20: 100 | C20: 850 | D20: 0 | E20: =(B20*C20)*D20 -> 0 | F20: 0 | G20: =(B20*C20)*F20 -> 0 | H20: 0 | I20: =(B20*C20)*H20 -> 0 | J20: 0 | K20: =(B20*C20)*J20 -> 0 | L20: 0 | M20: =(B20*C20)*L20 -> 0 | N20: 0 | O20: =(B20*C20)*N20 -> 0 | P20: 5 | Q20: =(B20*C20)*P20 -> 425000 | R20: 5 | S20: =(B20*C20)*R20 -> 425000 | T20: 5 | U20: =(B20*C20)*T20 -> 425000 | V20: 5 | W20: =(B20*C20)*V20 -> 425000 | X20: 5 | Y20: =(B20*C20)*X20 -> 425000 | Z20: 5 | AA20: =(B20*C20)*Z20 -> 425000
A21: Design Project Shop | B21: 150 | C21: 850 | D21: 0 | E21: =(B21*C21)*D21 -> 0 | F21: 0 | G21: =(B21*C21)*F21 -> 0 | H21: 0 | I21: =(B21*C21)*H21 -> 0 | J21: 0 | K21: =(B21*C21)*J21 -> 0 | L21: 0 | M21: =(B21*C21)*L21 -> 0 | N21: 0 | O21: =(B21*C21)*N21 -> 0 | P21: 4 | Q21: =(B21*C21)*P21 -> 510000 | R21: 4 | S21: =(B21*C21)*R21 -> 510000 | T21: 4 | U21: =(B21*C21)*T21 -> 510000 | V21: 4 | W21: =(B21*C21)*V21 -> 510000 | X21: 4 | Y21: =(B21*C21)*X21 -> 510000 | Z21: 4 | AA21: =(B21*C21)*Z21 -> 510000
A22: Design Project Shop | B22: 250 | C22: 850 | D22: 0 | E22: =(B22*C22)*D22 -> 0 | F22: 0 | G22: =(B22*C22)*F22 -> 0 | H22: 0 | I22: =(B22*C22)*H22 -> 0 | J22: 0 | K22: =(B22*C22)*J22 -> 0 | L22: 0 | M22: =(B22*C22)*L22 -> 0 | N22: 0 | O22: =(B22*C22)*N22 -> 0 | P22: 3 | Q22: =(B22*C22)*P22 -> 637500 | R22: 3 | S22: =(B22*C22)*R22 -> 637500 | T22: 3 | U22: =(B22*C22)*T22 -> 637500 | V22: 3 | W22: =(B22*C22)*V22 -> 637500 | X22: 3 | Y22: =(B22*C22)*X22 -> 637500 | Z22: 3 | AA22: =(B22*C22)*Z22 -> 637500
A23: Design Project Shop | B23: 350 | C23: 850 | D23: 0 | E23: =(B23*C23)*D23 -> 0 | F23: 0 | G23: =(B23*C23)*F23 -> 0 | H23: 0 | I23: =(B23*C23)*H23 -> 0 | J23: 0 | K23: =(B23*C23)*J23 -> 0 | L23: 0 | M23: =(B23*C23)*L23 -> 0 | N23: 0 | O23: =(B23*C23)*N23 -> 0 | P23: 3 | Q23: =(B23*C23)*P23 -> 892500 | R23: 3 | S23: =(B23*C23)*R23 -> 892500 | T23: 3 | U23: =(B23*C23)*T23 -> 892500 | V23: 3 | W23: =(B23*C23)*V23 -> 892500 | X23: 3 | Y23: =(B23*C23)*X23 -> 892500 | Z23: 3 | AA23: =(B23*C23)*Z23 -> 892500
A24: Design Project Shop | B24: 500 | C24: 850 | D24: 0 | E24: =(B24*C24)*D24 -> 0 | F24: 0 | G24: =(B24*C24)*F24 -> 0 | H24: 0 | I24: =(B24*C24)*H24 -> 0 | J24: 0 | K24: =(B24*C24)*J24 -> 0 | L24: 0 | M24: =(B24*C24)*L24 -> 0 | N24: 0 | O24: =(B24*C24)*N24 -> 0 | P24: 1 | Q24: =(B24*C24)*P24 -> 425000 | R24: 1 | S24: =(B24*C24)*R24 -> 425000 | T24: 1 | U24: =(B24*C24)*T24 -> 425000 | V24: 1 | W24: =(B24*C24)*V24 -> 425000 | X24: 1 | Y24: =(B24*C24)*X24 -> 425000 | Z24: 1 | AA24: =(B24*C24)*Z24 -> 425000
K25: =(B25*C25)*J25 -> 0 | M25: =(B25*C25)*L25 -> 0 | O25: =(B25*C25)*N25 -> 0 | Q25: =(B25*C25)*P25 -> 0 | S25: =(B25*C25)*R25 -> 0 | U25: =(B25*C25)*T25 -> 0 | W25: =(B25*C25)*V25 -> 0 | Y25: =(B25*C25)*X25 -> 0 | AA25: =(B25*C25)*Z25 -> 0
A26: Design Project office | B26: 100 | C26: 850 | D26: 0 | E26: =(B26*C26)*D26 -> 0 | F26: 0 | G26: =(B26*C26)*F26 -> 0 | H26: 0 | I26: =(B26*C26)*H26 -> 0 | J26: 0 | K26: =(B26*C26)*J26 -> 0 | L26: 0 | M26: =(B26*C26)*L26 -> 0 | N26: 0 | O26: =(B26*C26)*N26 -> 0 | P26: 5 | Q26: =(B26*C26)*P26 -> 425000 | R26: 5 | S26: =(B26*C26)*R26 -> 425000 | T26: 5 | U26: =(B26*C26)*T26 -> 425000 | V26: 5 | W26: =(B26*C26)*V26 -> 425000 | X26: 5 | Y26: =(B26*C26)*X26 -> 425000 | Z26: 5 | AA26: =(B26*C26)*Z26 -> 425000
A27: Design Project office | B27: 150 | C27: 850 | D27: 0 | E27: =(B27*C27)*D27 -> 0 | F27: 0 | G27: =(B27*C27)*F27 -> 0 | H27: 0 | I27: =(B27*C27)*H27 -> 0 | J27: 0 | K27: =(B27*C27)*J27 -> 0 | L27: 0 | M27: =(B27*C27)*L27 -> 0 | N27: 0 | O27: =(B27*C27)*N27 -> 0 | P27: 4 | Q27: =(B27*C27)*P27 -> 510000 | R27: 4 | S27: =(B27*C27)*R27 -> 510000 | T27: 4 | U27: =(B27*C27)*T27 -> 510000 | V27: 4 | W27: =(B27*C27)*V27 -> 510000 | X27: 4 | Y27: =(B27*C27)*X27 -> 510000 | Z27: 4 | AA27: =(B27*C27)*Z27 -> 510000
A28: Design Project office | B28: 250 | C28: 850 | D28: 0 | E28: =(B28*C28)*D28 -> 0 | F28: 0 | G28: =(B28*C28)*F28 -> 0 | H28: 0 | I28: =(B28*C28)*H28 -> 0 | J28: 0 | K28: =(B28*C28)*J28 -> 0 | L28: 0 | M28: =(B28*C28)*L28 -> 0 | N28: 0 | O28: =(B28*C28)*N28 -> 0 | P28: 3 | Q28: =(B28*C28)*P28 -> 637500 | R28: 3 | S28: =(B28*C28)*R28 -> 637500 | T28: 3 | U28: =(B28*C28)*T28 -> 637500 | V28: 3 | W28: =(B28*C28)*V28 -> 637500 | X28: 3 | Y28: =(B28*C28)*X28 -> 637500 | Z28: 3 | AA28: =(B28*C28)*Z28 -> 637500
A29: Design Project office | B29: 350 | C29: 850 | D29: 0 | E29: =(B29*C29)*D29 -> 0 | F29: 0 | G29: =(B29*C29)*F29 -> 0 | H29: 0 | I29: =(B29*C29)*H29 -> 0 | J29: 0 | K29: =(B29*C29)*J29 -> 0 | L29: 0 | M29: =(B29*C29)*L29 -> 0 | N29: 0 | O29: =(B29*C29)*N29 -> 0 | P29: 3 | Q29: =(B29*C29)*P29 -> 892500 | R29: 3 | S29: =(B29*C29)*R29 -> 892500 | T29: 3 | U29: =(B29*C29)*T29 -> 892500 | V29: 3 | W29: =(B29*C29)*V29 -> 892500 | X29: 3 | Y29: =(B29*C29)*X29 -> 892500 | Z29: 3 | AA29: =(B29*C29)*Z29 -> 892500
A30: Design Project office | B30: 500 | C30: 850 | D30: 0 | E30: =(B30*C30)*D30 -> 0 | F30: 0 | G30: =(B30*C30)*F30 -> 0 | H30: 0 | I30: =(B30*C30)*H30 -> 0 | J30: 0 | K30: =(B30*C30)*J30 -> 0 | L30: 0 | M30: =(B30*C30)*L30 -> 0 | N30: 0 | O30: =(B30*C30)*N30 -> 0 | P30: 1 | Q30: =(B30*C30)*P30 -> 425000 | R30: 1 | S30: =(B30*C30)*R30 -> 425000 | T30: 1 | U30: =(B30*C30)*T30 -> 425000 | V30: 1 | W30: =(B30*C30)*V30 -> 425000 | X30: 1 | Y30: =(B30*C30)*X30 -> 425000 | Z30: 1 | AA30: =(B30*C30)*Z30 -> 425000
D32: 0.1 | E32: =SUM(E10:E30) -> 0 | F32: 0.1 | G32: =SUM(G10:G30) -> 0 | H32: 0.1 | I32: =SUM(I10:I30) -> 0 | J32: 0.1 | K32: =SUM(K10:K30) -> 0 | L32: 0.1 | M32: =SUM(M10:M30) -> 0 | N32: 0.1 | O32: =SUM(O10:O30) -> 0 | P32: 0.1 | Q32: =SUM(Q10:Q30) -> 9182550 | R32: 0.1 | S32: =SUM(S10:S30) -> 9182550 | T32: 0.1 | U32: =SUM(U10:U30) -> 9182550 | V32: 0.1 | W32: =SUM(W10:W31) -> 9182550 | X32: 0.1 | Y32: =SUM(Y10:Y31) -> 9182550 | Z32: 0.1 | AA32: =SUM(AA10:AA31) -> 9182550
E33: =E32*D32 -> 0 | G33: =G32*F32 -> 0 | I33: =I32*H32 -> 0 | K33: =K32*J32 -> 0 | M33: =M32*L32 -> 0 | O33: =O32*N32 -> 0 | Q33: =Q32*P32 -> 918255 | S33: =S32*R32 -> 918255 | U33: =U32*T32 -> 918255 | W33: =W32*V32 -> 918255 | Y33: =Y32*X32 -> 918255 | AA33: =AA32*Z32 -> 918255 | AB33: =SUM(AA33,Y33,W33,U33,S33,Q33,O33,M33,K33,I33,G33,E33) -> 5509530
K34: =(B34*C34)*J34 -> 0 | M34: =(B34*C34)*L34 -> 0 | O34: =(B34*C34)*N34 -> 0 | Q34: =(B34*C34)*P34 -> 0 | S34: =(B34*C34)*R34 -> 0 | U34: =(B34*C34)*T34 -> 0 | W34: =(B34*C34)*V34 -> 0 | Y34: =(B34*C34)*X34 -> 0 | AA34: =(B34*C34)*Z34 -> 0
A35: contractor Project condo | B35: 26 | C35: 15000 | D35: 0 | E35: =(B35*C35)*D35 -> 0 | F35: 0 | G35: =(B35*C35)*F35 -> 0 | H35: 0 | I35: =(B35*C35)*H35 -> 0 | J35: 0 | K35: =(B35*C35)*J35 -> 0 | L35: 0 | M35: =(B35*C35)*L35 -> 0 | N35: 0 | O35: =(B35*C35)*N35 -> 0 | P35: 10 | Q35: =(B35*C35)*P35 -> 3900000 | R35: 10 | S35: =(B35*C35)*R35 -> 3900000 | T35: 10 | U35: =(B35*C35)*T35 -> 3900000 | V35: 10 | W35: =(B35*C35)*V35 -> 3900000 | X35: 10 | Y35: =(B35*C35)*X35 -> 3900000 | Z35: 10 | AA35: =(B35*C35)*Z35 -> 3900000
A36: contractor Project condo | B36: 33 | C36: 15000 | D36: 0 | E36: =(B36*C36)*D36 -> 0 | F36: 0 | G36: =(B36*C36)*F36 -> 0 | H36: 0 | I36: =(B36*C36)*H36 -> 0 | J36: 0 | K36: =(B36*C36)*J36 -> 0 | L36: 0 | M36: =(B36*C36)*L36 -> 0 | N36: 0 | O36: =(B36*C36)*N36 -> 0 | P36: 5 | Q36: =(B36*C36)*P36 -> 2475000 | R36: 5 | S36: =(B36*C36)*R36 -> 2475000 | T36: 5 | U36: =(B36*C36)*T36 -> 2475000 | V36: 5 | W36: =(B36*C36)*V36 -> 2475000 | X36: 5 | Y36: =(B36*C36)*X36 -> 2475000 | Z36: 5 | AA36: =(B36*C36)*Z36 -> 2475000
A37: contractor Project condo | B37: 64 | C37: 15000 | D37: 0 | E37: =(B37*C37)*D37 -> 0 | F37: 0 | G37: =(B37*C37)*F37 -> 0 | H37: 0 | I37: =(B37*C37)*H37 -> 0 | J37: 0 | K37: =(B37*C37)*J37 -> 0 | L37: 0 | M37: =(B37*C37)*L37 -> 0 | N37: 0 | O37: =(B37*C37)*N37 -> 0 | P37: 2 | Q37: =(B37*C37)*P37 -> 1920000 | R37: 2 | S37: =(B37*C37)*R37 -> 1920000 | T37: 2 | U37: =(B37*C37)*T37 -> 1920000 | V37: 2 | W37: =(B37*C37)*V37 -> 1920000 | X37: 2 | Y37: =(B37*C37)*X37 -> 1920000 | Z37: 2 | AA37: =(B37*C37)*Z37 -> 1920000
A38: contractor Project condo | B38: 100 | C38: 15000 | D38: 0 | E38: =(B38*C38)*D38 -> 0 | F38: 0 | G38: =(B38*C38)*F38 -> 0 | H38: 0 | I38: =(B38*C38)*H38 -> 0 | J38: 0 | K38: =(B38*C38)*J38 -> 0 | L38: 0 | M38: =(B38*C38)*L38 -> 0 | N38: 0 | O38: =(B38*C38)*N38 -> 0 | P38: 0 | Q38: =(B38*C38)*P38 -> 0 | R38: 0 | S38: =(B38*C38)*R38 -> 0 | T38: 0 | U38: =(B38*C38)*T38 -> 0 | V38: 0 | W38: =(B38*C38)*V38 -> 0 | X38: 0 | Y38: =(B38*C38)*X38 -> 0 | Z38: 0 | AA38: =(B38*C38)*Z38 -> 0
K39: =(B39*C39)*J39 -> 0 | M39: =(B39*C39)*L39 -> 0 | O39: =(B39*C39)*N39 -> 0 | Q39: =(B39*C39)*P39 -> 0 | S39: =(B39*C39)*R39 -> 0 | U39: =(B39*C39)*T39 -> 0 | W39: =(B39*C39)*V39 -> 0 | Y39: =(B39*C39)*X39 -> 0 | AA39: =(B39*C39)*Z39 -> 0
A40: contractor Project House | B40: 150 | C40: 15000 | D40: 0 | E40: =(B40*C40)*D40 -> 0 | F40: 0 | G40: =(B40*C40)*F40 -> 0 | H40: 0 | I40: =(B40*C40)*H40 -> 0 | J40: 0 | K40: =(B40*C40)*J40 -> 0 | L40: 0 | M40: =(B40*C40)*L40 -> 0 | N40: 0 | O40: =(B40*C40)*N40 -> 0 | P40: 10 | Q40: =(B40*C40)*P40 -> 22500000 | R40: 10 | S40: =(B40*C40)*R40 -> 22500000 | T40: 10 | U40: =(B40*C40)*T40 -> 22500000 | V40: 10 | W40: =(B40*C40)*V40 -> 22500000 | X40: 10 | Y40: =(B40*C40)*X40 -> 22500000 | Z40: 10 | AA40: =(B40*C40)*Z40 -> 22500000
A41: contractor Project House | B41: 250 | C41: 15000 | D41: 0 | E41: =(B41*C41)*D41 -> 0 | F41: 0 | G41: =(B41*C41)*F41 -> 0 | H41: 0 | I41: =(B41*C41)*H41 -> 0 | J41: 0 | K41: =(B41*C41)*J41 -> 0 | L41: 0 | M41: =(B41*C41)*L41 -> 0 | N41: 0 | O41: =(B41*C41)*N41 -> 0 | P41: 5 | Q41: =(B41*C41)*P41 -> 18750000 | R41: 5 | S41: =(B41*C41)*R41 -> 18750000 | T41: 5 | U41: =(B41*C41)*T41 -> 18750000 | V41: 5 | W41: =(B41*C41)*V41 -> 18750000 | X41: 5 | Y41: =(B41*C41)*X41 -> 18750000 | Z41: 5 | AA41: =(B41*C41)*Z41 -> 18750000
A42: contractor Project House | B42: 350 | C42: 15000 | D42: 0 | E42: =(B42*C42)*D42 -> 0 | F42: 0 | G42: =(B42*C42)*F42 -> 0 | H42: 0 | I42: =(B42*C42)*H42 -> 0 | J42: 0 | K42: =(B42*C42)*J42 -> 0 | L42: 0 | M42: =(B42*C42)*L42 -> 0 | N42: 0 | O42: =(B42*C42)*N42 -> 0 | P42: 2 | Q42: =(B42*C42)*P42 -> 10500000 | R42: 2 | S42: =(B42*C42)*R42 -> 10500000 | T42: 2 | U42: =(B42*C42)*T42 -> 10500000 | V42: 2 | W42: =(B42*C42)*V42 -> 10500000 | X42: 2 | Y42: =(B42*C42)*X42 -> 10500000 | Z42: 2 | AA42: =(B42*C42)*Z42 -> 10500000
A43: contractor Project House | B43: 500 | C43: 15000 | D43: 0 | E43: =(B43*C43)*D43 -> 0 | F43: 0 | G43: =(B43*C43)*F43 -> 0 | H43: 0 | I43: =(B43*C43)*H43 -> 0 | J43: 0 | K43: =(B43*C43)*J43 -> 0 | L43: 0 | M43: =(B43*C43)*L43 -> 0 | N43: 0 | O43: =(B43*C43)*N43 -> 0 | P43: 0 | Q43: =(B43*C43)*P43 -> 0 | R43: 0 | S43: =(B43*C43)*R43 -> 0 | T43: 0 | U43: =(B43*C43)*T43 -> 0 | V43: 0 | W43: =(B43*C43)*V43 -> 0 | X43: 0 | Y43: =(B43*C43)*X43 -> 0 | Z43: 0 | AA43: =(B43*C43)*Z43 -> 0
K44: =(B44*C44)*J44 -> 0 | M44: =(B44*C44)*L44 -> 0 | O44: =(B44*C44)*N44 -> 0 | Q44: =(B44*C44)*P44 -> 0 | S44: =(B44*C44)*R44 -> 0 | U44: =(B44*C44)*T44 -> 0 | W44: =(B44*C44)*V44 -> 0 | Y44: =(B44*C44)*X44 -> 0 | AA44: =(B44*C44)*Z44 -> 0
...

Sheet Infrastructure (Direct Cost)
A1: Infrastructure
A2: Year1
A3: CATEGORY | B3: 43586 | C3: 43617 | D3: 43647 | E3: 43678 | F3: 43709 | G3: 43739 | H3: 43770 | I3: 43800 | J3: 43831 | K3: 43862 | L3: 43891 | M3: 43922 | N3: Total
A11: Year2
A12: CATEGORY | B12: 43952 | C12: 43983 | D12: 44013 | E12: 44044 | F12: 44075 | G12: 44105 | H12: 44136 | I12: 44166 | J12: 44197 | K12: 44228 | L12: 44256 | M12: 44287 | N12: Total
A20: Year3
A21: CATEGORY | B21: 44317 | C21: 44348 | D21: 44378 | E21: 44409 | F21: 44440 | G21: 44470 | H21: 44501 | I21: 44531 | J21: 44562 | K21: 44593 | L21: 44621 | M21: 44652 | N21: Total
A31: Year1 | B31: =SUM(B5:B10) -> 0 | C31: =SUM(C5:C10) -> 0 | D31: =SUM(D5:D10) -> 0 | E31: =SUM(E5:E10) -> 0 | F31: =SUM(F5:F10) -> 0 | G31: =SUM(G5:G10) -> 0 | H31: =SUM(H5:H10) -> 0 | I31: =SUM(I5:I10) -> 0 | ... M31: =SUM(M5:M10) -> 0
A32: Year2 | B32: =SUM(B14:B19) -> 0 | C32: =SUM(C14:C19) -> 0 | D32: =SUM(D14:D19) -> 0 | E32: =SUM(E14:E19) -> 0 | F32: =SUM(F14:F19) -> 0 | G32: =SUM(G14:G19) -> 0 | H32: =SUM(H14:H19) -> 0 | I32: =SUM(I14:I19) -> 0 | ... M32: =SUM(M14:M19) -> 0
A33: Year3 | B33: =SUM(B23:B29) -> 0 | C33: =SUM(C23:C29) -> 0 | D33: =SUM(D23:D29) -> 0 | E33: =SUM(E23:E29) -> 0 | F33: =SUM(F23:F29) -> 0 | G33: =SUM(G23:G29) -> 0 | H33: =SUM(H23:H29) -> 0 | I33: =SUM(I23:I29) -> 0 | ... M33: =SUM(M23:M29) -> 0
A37: รายละเอียด Spec Infra

Sheet Developer (Direct Cost)
A1: Operation (IT Developer or Engineer)
A2: Year1
B3: Growth | C3: 43586 | D3: 43617 | E3: 43647 | F3: 43678 | G3: 43709 | H3: 43739 | I3: 43770 | J3: 43800 | K3: 43831 | L3: 43862 | M3: 43891 | N3: 43922 | O3: Total
A11: Year2
A12: CATEGORY | B12: Growth | C12: 43952 | D12: 43983 | E12: 44013 | F12: 44044 | G12: 44075 | H12: 44105 | I12: 44136 | J12: 44166 | K12: 44197 | L12: 44228 | M12: 44256 | N12: 44287 | O12: Total
A20: Year3
A21: CATEGORY | B21: Growth | C21: 44317 | D21: 44348 | E21: 44378 | F21: 44409 | G21: 44440 | H21: 44470 | I21: 44501 | J21: 44531 | K21: 44562 | L21: 44593 | M21: 44621 | N21: 44652 | O21: Total
A31: Year1 | C31: =SUM(C5:C10) -> 0 | D31: =SUM(D5:D10) -> 0 | E31: =SUM(E5:E10) -> 0 | F31: =SUM(F5:F10) -> 0 | G31: =SUM(G5:G10) -> 0 | H31: =SUM(H5:H10) -> 0 | I31: =SUM(I5:I10) -> 0 | J31: =SUM(J5:J10) -> 0 | ... N31: =SUM(N5:N10) -> 0
A32: Year2 | C32: =SUM(C14:C19) -> 0 | D32: =SUM(D14:D19) -> 0 | E32: =SUM(E14:E19) -> 0 | F32: =SUM(F14:F19) -> 0 | G32: =SUM(G14:G19) -> 0 | H32: =SUM(H14:H19) -> 0 | I32: =SUM(I14:I19) -> 0 | J32: =SUM(J14:J19) -> 0 | ... N32: =SUM(N14:N19) -> 0
A33: Year3 | C33: =SUM(C23:C29) -> 0 | D33: =SUM(D23:D29) -> 0 | E33: =SUM(E23:E29) -> 0 | F33: =SUM(F23:F29) -> 0 | G33: =SUM(G23:G29) -> 0 | H33: =SUM(H23:H29) -> 0 | I33: =SUM(I23:I29) -> 0 | J33: =SUM(J23:J29) -> 0 | ... N33: =SUM(N23:N29) -> 0

Sheet Marketing (SGA)
A1: Marketing
A2: Year 1
A3: CATEGORY | E3: 43831 | G3: 43862 | I3: 43891 | K3: 43922 | M3: 43952 | O3: 43983 | Q3: 44013 | S3: 44044 | U3: 44075 | W3: 44105 | Y3: 44136 | AA3: 44166 | AB3: Total
A5: Google ad | G5: 100000 | I5: 100000 | K5: 100000 | M5: 100000 | O5: 100000 | Q5: 100000 | S5: 600000 | U5: 600000 | W5: 600000 | Y5: 600000 | AA5: 600000
A6: facebook | G6: 600000 | I6: 600000 | K6: 600000 | M6: 600000 | O6: 600000 | Q6: 600000 | S6: 2500000 | U6: 2500000 | W6: 2500000 | Y6: 2500000 | AA6: 2500000
A7: Blog | G7: 200000 | I7: 200000 | K7: 200000 | M7: 200000 | O7: 200000 | Q7: 200000 | S7: 600000 | U7: 600000 | W7: 600000 | Y7: 600000 | AA7: 600000
A8: youtub | S8: 2000000 | U8: 2000000 | W8: 2000000 | Y8: 2000000 | AA8: 2000000
A10: Architecture Expo | I10: 2500000
A11: บ้านและสวนแฟร์ | G11: 500000 | S11: 500000 | W11: 500000
A12: Event | AB12: =SUM(E12:AA12) -> 0
A13: Interior Company Visit | G13: 125000 | I13: 125000 | K13: 125000 | M13: 125000 | O13: 125000 | Q13: 125000 | S13: 125000 | U13: 125000 | W13: 125000 | Y13: 125000 | AA13: 125000 | AB13: =SUM(AA13,Y13,W13,U13,S13,Q13,O13,M13,K13,I13,G13,E13) -> 1375000
A14: Interior and Decorate Shop | G14: 125000 | I14: 125000 | K14: 125000 | M14: 125000 | O14: 125000 | Q14: 125000 | S14: 125000 | U14: 125000 | W14: 125000 | Y14: 125000 | AA14: 125000 | AB14: =SUM(AA14,Y14,W14,U14,S14,Q14,O14,M14,K14,I14,G14,E14) -> 1375000
A15: Billboard
A16: Department Store Event
A17: สัมมนา
E18: =SUM(E5:E17) -> 0 | G18: =SUM(G5:G17) -> 1650000 | I18: =SUM(I5:I17) -> 3650000 | K18: =SUM(K5:K17) -> 1150000 | M18: =SUM(M5:M17) -> 1150000 | O18: =SUM(O5:O17) -> 1150000 | Q18: =SUM(Q5:Q17) -> 1150000 | S18: =SUM(S5:S17) -> 6450000 | U18: =SUM(U5:U17) -> 5950000 | W18: =SUM(W5:W17) -> 6450000 | Y18: =SUM(Y5:Y17) -> 5950000 | AA18: =SUM(AA5:AA17) -> 5950000 | AB18: =SUM(AA18,Y18,W18,U18,S18,Q18,O18,M18,K18,I18,G18,E18) -> 40650000
A20: Year 2
A21: CATEGORY | E21: 43831 | G21: 43862 | I21: 43891 | K21: 43922 | M21: 43952 | O21: 43983 | Q21: 44013 | S21: 44044 | U21: 44075 | W21: 44105 | Y21: 44136 | AA21: 44166 | AB21: Total
A23: Google ad | E23: 600000 | G23: 600000 | I23: 600000 | K23: 600000 | M23: 600000 | O23: 600000 | Q23: 1000000 | S23: 1000000 | U23: 1000000 | W23: 1000000 | Y23: 1000000 | AA23: 1000000
A24: facebook | E24: 8000000 | G24: 8000000 | I24: 8000000 | K24: 8000000 | M24: 8000000 | O24: 8000000 | Q24: 16000000 | S24: 16000000 | U24: 16000000 | W24: 16000000 | Y24: 16000000 | AA24: 16000000
A25: Blog | E25: 1000000 | G25: 1000000 | I25: 1000000 | K25: 1000000 | M25: 1000000 | O25: 1000000 | Q25: 3000000 | S25: 3000000 | U25: 3000000 | W25: 3000000 | Y25: 3000000 | AA25: 3000000
A26: youtub | E26: 6000000 | G26: 6000000 | I26: 6000000 | K26: 6000000 | M26: 6000000 | O26: 6000000 | Q26: 12000000 | S26: 12000000 | U26: 12000000 | W26: 12000000 | Y26: 12000000 | AA26: 12000000
A28: Architecture Expo | I28: 3500000
A29: บ้านและสวนแฟร์ | G29: 1000000 | S29: 1000000 | W29: 1000000
A30: Event | K30: 1500000 | U30: 1500000 | AA30: 5000000 | AB30: =SUM(E30:AA30) -> 8000000
A31: Interior Company Visit | G31: 125000 | I31: 125000 | K31: 125000 | M31: 125000 | O31: 125000 | Q31: 125000 | S31: 125000 | U31: 125000 | W31: 125000 | Y31: 125000 | AA31: 125000 | AB31: =SUM(AA31,Y31,W31,U31,S31,Q31,O31,M31,K31,I31,G31,E31) -> 1375000
A32: Interior and Decorate Shop | G32: 125000 | I32: 125000 | K32: 125000 | M32: 125000 | O32: 125000 | Q32: 125000 | S32: 125000 | U32: 125000 | W32: 125000 | Y32: 125000 | AA32: 125000 | AB32: =SUM(AA32,Y32,W32,U32,S32,Q32,O32,M32,K32,I32,G32,E32) -> 1375000
A33: Billboard | Q33: 1000000 | S33: 1000000 | U33: 1000000 | W33: 1000000 | Y33: 1000000 | AA33: 1000000
A35: สัมมนา
E36: =SUM(E23:E35) -> 15600000 | G36: =SUM(G23:G35) -> 16850000 | I36: =SUM(I23:I35) -> 19350000 | K36: =SUM(K23:K35) -> 17350000 | M36: =SUM(M23:M35) -> 15850000 | O36: =SUM(O23:O35) -> 15850000 | Q36: =SUM(Q23:Q35) -> 33250000 | S36: =SUM(S23:S35) -> 34250000 | U36: =SUM(U23:U35) -> 34750000 | W36: =SUM(W23:W35) -> 34250000 | Y36: =SUM(Y23:Y35) -> 33250000 | AA36: =SUM(AA23:AA35) -> 38250000 | AB36: =SUM(AA36,Y36,W36,U36,S36,Q36,O36,M36,K36,I36,G36,E36) -> 308850000
A37: Year 3
A38: CATEGORY | E38: 43831 | G38: 43862 | I38: 43891 | K38: 43922 | M38: 43952 | O38: 43983 | Q38: 44013 | S38: 44044 | U38: 44075 | W38: 44105 | Y38: 44136 | AA38: 44166 | AB38: Total
A40: Google ad | E40: 1000000 | G40: 1000000 | I40: 1000000 | K40: 1000000 | M40: 1000000 | O40: 1000000 | Q40: 1000000 | S40: 1000000 | U40: 1000000 | W40: 1000000 | Y40: 1000000 | AA40: 1000000
A41: facebook | E41: 30000000 | G41: 30000000 | I41: 30000000 | K41: 30000000 | M41: 30000000 | O41: 30000000 | Q41: 30000000 | S41: 30000000 | U41: 30000000 | W41: 30000000 | Y41: 30000000 | AA41: 30000000
A42: Blog | E42: 3000000 | G42: 3000000 | I42: 3000000 | K42: 3000000 | M42: 3000000 | O42: 3000000 | Q42: 3000000 | S42: 3000000 | U42: 3000000 | W42: 3000000 | Y42: 3000000 | AA42: 3000000
A43: youtub | E43: 24000000 | G43: 24000000 | I43: 24000000 | K43: 24000000 | M43: 24000000 | O43: 24000000 | Q43: 24000000 | S43: 24000000 | U43: 24000000 | W43: 24000000 | Y43: 24000000 | AA43: 24000000
A45: Architecture Expo | I45: 2500000
A46: บ้านและสวนแฟร์ | G46: 500000 | S46: 500000 | W46: 500000
A47: Event | K47: 1500000 | U47: 1500000 | AA47: 10000000 | AB47: =SUM(E47:AA47) -> 13000000
A48: Interior Company Visit | G48: 125000 | I48: 125000 | K48: 125000 | M48: 125000 | O48: 125000 | Q48: 125000 | S48: 125000 | U48: 125000 | W48: 125000 | Y48: 125000 | AA48: 125000 | AB48: =SUM(AA48,Y48,W48,U48,S48,Q48,O48,M48,K48,I48,G48,E48) -> 1375000
...

Sheet Officer ( SGA) พนักงาน
C1: Officer
A2: Year1 | B2: Year1 | C2: Year1
E3: Growth | F3: 43831 | G3: 43862 | H3: 43891 | I3: 43922 | J3: 43952 | K3: 43983 | L3: 44013 | M3: 44044 | N3: 44075 | O3: 44105 | P3: 44136 | Q3: 44166 | R3: Total
B6: General Manager | C6: General Manager | D6: 1
B7: BD | C7: BD | D7: 1
B8: Sale officer | C8: Sale officer | D8: 4 | E8: 200 /4 per month | F8: 120000 | G8: 120000 | H8: 120000 | I8: 120000 | J8: 120000 | K8: 120000 | L8: 240000 | M8: 240000 | N8: 240000 | O8: 240000 | P8: 240000 | Q8: 240000
B10: Platform Support | D10: 1
D11: 2 | F11: 180000 | G11: 180000 | H11: 180000 | I11: 180000 | J11: 180000 | K11: 180000 | L11: 450000 | M11: 450000 | N11: 450000 | O11: 450000 | P11: 450000 | Q11: 450000
D12: 3
A17: Marketing | B17: Marketing | D17: 3
E19: 200 /per month | F19: 140000 | G19: 140000 | H19: 140000 | I19: 140000 | J19: 140000 | K19: 140000 | L19: 140000 | M19: 140000 | N19: 140000 | O19: 140000 | P19: 140000 | Q19: 140000
B24: digital marketing | D24: 6
E28: 200 /per month | F28: 220000 | G28: 220000 | H28: 220000 | I28: 220000 | J28: 220000 | K28: 220000 | L28: 220000 | M28: 220000 | N28: 220000 | O28: 220000 | P28: 220000 | Q28: 220000
B33: Production House | D33: 4 | E33: 200 /per month | F33: 120000 | G33: 120000 | H33: 120000 | I33: 120000 | J33: 120000 | K33: 120000 | L33: 240000 | M33: 240000 | N33: 240000 | O33: 240000 | P33: 240000 | Q33: 240000
D34: 2 | E34: 200 /per month | F34: 60000 | G34: 60000 | H34: 60000 | I34: 60000 | J34: 60000 | K34: 60000 | L34: 120000 | M34: 120000 | N34: 120000 | O34: 120000 | P34: 120000 | Q34: 120000
D35: 4 | E35: 200 /per month | F35: 120000 | G35: 120000 | H35: 120000 | I35: 120000 | J35: 120000 | K35: 120000 | L35: 240000 | M35: 240000 | N35: 240000 | O35: 240000 | P35: 240000 | Q35: 240000
D36: 1 | E36: 200 /per month | F36: 35000 | G36: 35000 | H36: 35000 | I36: 35000 | J36: 35000 | K36: 35000 | L36: 70000 | M36: 70000 | N36: 70000 | O36: 70000 | P36: 70000 | Q36: 70000
D37: 4 | E37: 200 /per month | F37: 100000 | G37: 100000 | H37: 100000 | I37: 100000 | J37: 100000 | K37: 100000 | L37: 200000 | M37: 200000 | N37: 200000 | O37: 200000 | P37: 200000 | Q37: 200000
D38: 4 | E38: 200 /per month | F38: 36000 | G38: 36000 | H38: 36000 | I38: 36000 | J38: 36000 | K38: 36000 | L38: 80000 | M38: 80000 | N38: 80000 | O38: 80000 | P38: 80000 | Q38: 80000
D39: 1 | E39: 200 /per month | F39: 28000 | G39: 28000 | H39: 28000 | I39: 28000 | J39: 28000 | K39: 28000 | L39: 50000 | M39: 50000 | N39: 50000 | O39: 50000 | P39: 50000 | Q39: 50000
D40: 4 | E40: 200 /per month | F40: 72000 | G40: 72000 | H40: 72000 | I40: 72000 | J40: 72000 | K40: 72000 | L40: 150000 | M40: 150000 | N40: 150000 | O40: 150000 | P40: 150000 | Q40: 150000
D41: 1 | E41: 200 /per month | F41: 55000 | G41: 55000 | H41: 55000 | I41: 55000 | J41: 55000 | K41: 55000 | L41: 120000 | M41: 120000 | N41: 120000 | O41: 120000 | P41: 120000 | Q41: 120000
A43: Software | B43: Project Design | C43: Develop Functional Specifications
C44: Develop System Architecture
C45: Develop Preliminary Design Specification
C46: Develop Detailed Design Specifications
C47: Develop Acceptance Test Plan
B49: System Development | C49: Develop Components
C50: Development Acceptance Test Package
C51: Perform Unit/Integration Test
B53: Project Management | C53: Internal Status Meetings/Reports
C54: Configuration Management
C55: Quality Assurance
C56: Overall Project Management
B58: Test and Delivery | C58: Install System
C59: Train Customers
C60: Perform Acceptance Test
C61: Perform Post Project Review
C62: Achieve Materials
B64: Infarstructuer | C64: On-Clound Server
...

Sheet Other Expense (SGA)
A1: Other Expense
A2: Year1
A3: CATEGORY | B3: 43586 | C3: 43617 | D3: 43647 | E3: 43678 | F3: 43709 | G3: 43739 | H3: 43770 | I3: 43800 | J3: 43831 | K3: 43862 | L3: 43891 | M3: 43922 | N3: Total
A11: Year2
A12: CATEGORY | B12: 43952 | C12: 43983 | D12: 44013 | E12: 44044 | F12: 44075 | G12: 44105 | H12: 44136 | I12: 44166 | J12: 44197 | K12: 44228 | L12: 44256 | M12: 44287 | N12: Total
A20: Year3
A21: CATEGORY | B21: 44317 | C21: 44348 | D21: 44378 | E21: 44409 | F21: 44440 | G21: 44470 | H21: 44501 | I21: 44531 | J21: 44562 | K21: 44593 | L21: 44621 | M21: 44652 | N21: Total
A32: Year1 | B32: =SUM(B5:B10) -> 0 | C32: =SUM(C5:C10) -> 0 | D32: =SUM(D5:D10) -> 0 | E32: =SUM(E5:E10) -> 0 | F32: =SUM(F5:F10) -> 0 | G32: =SUM(G5:G10) -> 0 | H32: =SUM(H5:H10) -> 0 | I32: =SUM(I5:I10) -> 0 | ... M32: =SUM(M5:M10) -> 0
A33: Year2 | B33: =SUM(B14:B19) -> 0 | C33: =SUM(C14:C19) -> 0 | D33: =SUM(D14:D19) -> 0 | E33: =SUM(E14:E19) -> 0 | F33: =SUM(F14:F19) -> 0 | G33: =SUM(G14:G19) -> 0 | H33: =SUM(H14:H19) -> 0 | I33: =SUM(I14:I19) -> 0 | ... M33: =SUM(M14:M19) -> 0
A34: Year3 | B34: =SUM(B23:B29) -> 0 | C34: =SUM(C23:C29) -> 0 | D34: =SUM(D23:D29) -> 0 | E34: =SUM(E23:E29) -> 0 | F34: =SUM(F23:F29) -> 0 | G34: =SUM(G23:G29) -> 0 | H34: =SUM(H23:H29) -> 0 | I34: =SUM(I23:I29) -> 0 | ... M34: =SUM(M23:M29) -> 0

Sheet Summary Year (original)
B2: Original | C2: Year 1 | D2: Year 2 | E2: Year 3
B3: =REVENUE!A7 -> xxxx | C3: =REVENUE!AA7 -> 0 | D3: =REVENUE!AA288 -> 0 | E3: =REVENUE!#REF! -> #REF!
B4: =REVENUE!A8 -> 0 | C4: =REVENUE!AA281 -> 0 | D4: =REVENUE!AA289 -> 0 | E4: =REVENUE!AA577 -> 0
B5: =REVENUE!A281 -> 0 | C5: =REVENUE!AA281 -> 0 | D5: =REVENUE!AA290 -> 0 | E5: =REVENUE!AA592 -> 0
B8: P/L | C8: Year 1 | D8: Year 2 | E8: Year 3 | F8: Total | G8: %
B9: ='Budget Plan'!A20 -> Revenue | C9: =SUM(C11:C14) -> 0 | D9: =SUM(D11:D14) -> 0 | E9: =SUM(E11:E14) -> 0 | F9: =SUM(C9:E9) -> 0 | G9: =F9/$F$9 -> #DIV/0!
B10: Develop for INET
B11: ='Budget Plan'!A22 -> Revenue From sales | C11: =SUM('Budget Plan'!G22:R22) -> 0 | D11: =SUM('Budget Plan'!S22:AD22) -> 0 | E11: =SUM('Budget Plan'!AE22:AP22) -> 0 | F11: =SUM(C11:E11) -> 0 | G11: =F11/$F$9 -> #DIV/0!
B15: ='Budget Plan'!A28 -> Direct Cost | C15: =SUM(C16:C18) -> 0 | D15: =SUM(D16:D18) -> 0 | E15: =SUM(E16:E18) -> 0 | F15: =SUM(C15:E15) -> 0 | G15: =F15/$F$9 -> #DIV/0!
B16: ='Budget Plan'!A29 -> Onetime | C16: =SUM('Budget Plan'!G29:R29) -> 0 | D16: =SUM('Budget Plan'!S29:AD29) -> 0 | E16: =SUM('Budget Plan'!AE29:AP29) -> 0 | F16: =SUM(C16:E16) -> 0 | G16: =F16/$F$9 -> #DIV/0!
B17: ='Budget Plan'!A33 -> 0 | C17: =SUM('Budget Plan'!G33:R33) -> 0 | D17: =SUM('Budget Plan'!S33:AD33) -> 0 | E17: =SUM('Budget Plan'!AE33:AP33) -> 0 | F17: =SUM(C17:E17) -> 0 | G17: =F17/$F$9 -> #DIV/0!
B18: ='Budget Plan'!A50 -> Revenue Share | C18: =SUM('Budget Plan'!G50:R50) -> 0 | D18: =SUM('Budget Plan'!S50:AD50) -> 0 | E18: =SUM('Budget Plan'!AE50:AP50) -> 0 | F18: =SUM(C18:E18) -> 0 | G18: =F18/$F$9 -> #DIV/0!
B19: ='Budget Plan'!A53 -> Gross Profit | C19: =SUM('Budget Plan'!G53:R53) -> 0 | D19: =SUM('Budget Plan'!S53:AD53) -> 0 | E19: =SUM('Budget Plan'!AE53:AE53) -> 0 | F19: =SUM(C19:E19) -> 0 | G19: =F19/$F$9 -> #DIV/0!
B20: ='Budget Plan'!A54 -> SG&A | C20: =SUM('Budget Plan'!G54:R54) -> #REF! | D20: =SUM('Budget Plan'!S54:AD54) -> #REF! | E20: =SUM('Budget Plan'!AE54:AP54) -> #REF! | F20: =SUM(C20:E20) -> #REF! | G20: =F20/$F$9 -> #REF!
B21: ='Budget Plan'!A76 -> Net Profit | C21: =SUM('Budget Plan'!G76:R76) -> #REF! | D21: =SUM('Budget Plan'!S76:AD76) -> #REF! | E21: =SUM('Budget Plan'!AE76:AP76) -> #REF! | F21: =SUM(C21:E21) -> #REF! | G21: =F21/$F$9 -> #REF!
B22: RE | C22: ='Budget Plan'!R77 -> #REF! | D22: ='Budget Plan'!AD77 -> #REF! | E22: ='Budget Plan'!AP77 -> #REF! | F22: =SUM(C22:E22) -> #REF!
B24: Cash Flow | C24: Year 1 | D24: Year 2 | E24: Year 3 | F24: Total | G24: %
B25: Cash In | C25: =SUM(C26:C27) -> 0 | D25: =SUM(D26:D27) -> 0 | E25: =SUM(E26:E27) -> 0 | F25: =SUM(C25:E25) -> 0 | G25: =F25/$F$25 -> #DIV/0!
B26: Develop for INET | C26: =SUM('Budget Plan'!G80:R80) -> 0 | D26: =SUM('Budget Plan'!H80:S80) -> 0 | E26: =SUM('Budget Plan'!I80:T80) -> 0 | F26: =SUM(C26:E26) -> 0 | G26: =F26/$F$25 -> #DIV/0!
B27: Revenue from customer | C27: =SUM('Budget Plan'!G81:R82) -> 0 | D27: =SUM('Budget Plan'!S81:AD82) -> 0 | E27: =SUM('Budget Plan'!AE81:AP82) -> 0 | F27: =SUM(C27:E27) -> 0 | G27: =F27/$F$25 -> #DIV/0!
B28: Cash Out | C28: =SUM(C29,C32:C33) -> #REF! | D28: =SUM(D29,D32:D33) -> #REF! | E28: =SUM(E29,E32:E33) -> #REF! | F28: =SUM(C28:E28) -> #REF! | G28: =F28/$F$25 -> #REF!
B29: ='Budget Plan'!A84 -> Direct Cost | C29: =SUM(C30:C31) -> 0 | D29: =SUM(D30:D31) -> 0 | E29: =SUM(E30:E31) -> 0 | F29: =SUM(C29:E29) -> 0 | G29: =F29/$F$25 -> #DIV/0!
B30: ='Budget Plan'!A85 -> One Time | C30: =SUM('Budget Plan'!G85:R85) -> 0 | D30: =SUM('Budget Plan'!S85:AD85) -> 0 | E30: =SUM('Budget Plan'!AE85:AP85) -> 0 | F30: =SUM(C30:E30) -> 0 | G30: =F30/$F$25 -> #DIV/0!
B31: ='Budget Plan'!A88 -> Recurring | C31: =SUM('Budget Plan'!G88:R88) -> 0 | D31: =SUM('Budget Plan'!S88:AD88) -> 0 | E31: =SUM('Budget Plan'!AE88:AP88) -> 0 | F31: =SUM(C31:E31) -> 0 | G31: =F31/$F$25 -> #DIV/0!
B32: ='Budget Plan'!A92 -> Revshare | C32: =SUM('Budget Plan'!G92:R92) -> 0 | D32: =SUM('Budget Plan'!S92:AD92) -> 0 | E32: =SUM('Budget Plan'!AE92:AP92) -> 0 | F32: =SUM(C32:E32) -> 0 | G32: =F32/$F$25 -> #DIV/0!
B33: ='Budget Plan'!A93 -> SG&A | C33: =SUM(C34:C34) -> #REF! | D33: =SUM(D34:D34) -> #REF! | E33: =SUM(E34:E34) -> #REF! | F33: =SUM(C33:E33) -> #REF! | G33: =F33/$F$25 -> #REF!
B34: Sale & Management | C34: =SUM('Budget Plan'!G93:R93) -> #REF! | D34: =SUM('Budget Plan'!S93:AD93) -> #REF! | E34: =SUM('Budget Plan'!AE93:AP93) -> #REF! | F34: =SUM(C34:E34) -> #REF! | G34: =F34/$F$25 -> #REF!
B35: ='Budget Plan'!A96 -> Net Cash | C35: =SUM('Budget Plan'!G96:R96) -> #REF! | D35: =SUM('Budget Plan'!S96:AD96) -> #REF! | E35: =SUM('Budget Plan'!AE96:AP96) -> #REF! | F35: =SUM(C35:E35) -> #REF! | G35: =F35/$F$25 -> #REF!
B36: Cash CF | C36: ='Budget Plan'!R98 -> #REF! | D36: ='Budget Plan'!AD98 -> #REF! | E36: ='Budget Plan'!AP98 -> #REF! | F36: =SUM(C36:E36) -> #REF!

Sheet BOM 4 vm 99.90% Disk SSD
C1: เอกสารสนับสนุน (แบบฟอร์ม) | F1: หน่วยงาน : ส่วนงานบริหารต้นทุนองค์กร | H1: version 1.0 | I1: วันที่บังคับใช้ : 09/05/2016
C2: หัวข้อ : BOM (Bill of Material) Cost | F2: FM-BOM Cost | H2: ผู้อนุมัติ : | I2: หรรษา นวาระพรรณ | J2: หน้า : 1/1
B3: Cost Project :MBKC
B4: Sale : Pimpan Deachapiyamit
B5: Pre-sale : Vatcharapong Tavichai | F5: Actual Cost | G5: =G35 -> #REF! | H5: Eng. Cost/Year | I5: =I35 -> #REF!
B6: Date : 17/02/2017
B7: Version : 6
B8: Cost By : Supawadee
D9: Contract | E9: 2 | F9: Month | I9: 0.8
A10: Vendor | B10: =B3 -> Cost Project :MBKC | C10: Unit | E10: Unit/Price | F10: Price | G10: Actual Cost | I10: Eng. Cost | J10: Eng. Cost/Month
B11: One Time Charge
B12: Manage Service By Project Team | C12: 0 | F12: =C12*E12 -> 0 | G12: =F12*$E$9 -> 0 | H12: =G12/$G$5 -> #REF! | I12: =G12/$I$9 -> 0 | J12: =I12/$E$9 -> 0
B13: Implement PHP&Apache by Project Team | C13: 0 | D13: VM | E13: =5000*0.8 -> 4000 | F13: =C13*E13 -> 0 | G13: =F13 -> 0 | H13: =G13/$G$5 -> #REF! | I13: =G13/$I$9 -> 0 | J13: =I13/$E$9 -> 0
B15: ToTal
B16: Recurring
B17: MsCloud (VDC) | C17: 0 | F17: =C17*E17 -> 0 | G17: =F17*$E$9 -> 0 | H17: =G17/$G$5 -> #REF! | I17: =G17/$I$9 -> 0 | J17: =I17/$E$9 -> 0
A18: INET | B18: VCPU(GHz) | C18: =#REF! -> #REF! | D18: GHz | E18: =105*0.8 -> 84 | F18: =C18*E18 -> #REF! | G18: =F18*$E$9 -> #REF! | H18: =G18/$G$5 -> #REF! | I18: =G18/$I$9 -> #REF! | J18: =I18/$E$9 -> #REF!
A19: INET | B19: Vram(GB) | C19: =#REF! -> #REF! | D19: GB | E19: =100*0.8 -> 80 | F19: =C19*E19 -> #REF! | G19: =F19*$E$9 -> #REF! | H19: =G19/$G$5 -> #REF! | I19: =G19/$I$9 -> #REF! | J19: =I19/$E$9 -> #REF!
A20: INET | B20: VDisk (SSD) +Backup snapshot 4 copy & Snapmirror 7 copy | C20: =#REF! -> #REF! | D20: GB | E20: =3*0.8 -> 2.4 | F20: =C20*E20 -> #REF! | G20: =F20*$E$9 -> #REF! | H20: =G20/$G$5 -> #REF! | I20: =G20/$I$9 -> #REF! | J20: =I20/$E$9 -> #REF!
A21: INET | B21: VDisk (Hybrid) add on RTO/RPO 4 hr. | C21: =C20*4*0 -> #REF! | D21: GB | E21: =2.8*0.8 -> 2.24 | F21: =C21*E21 -> #REF! | G21: =F21*$E$9 -> #REF! | H21: =G21/$G$5 -> #REF! | I21: =G21/$I$9 -> #REF! | J21: =I21/$E$9 -> #REF!
A22: INET | B22: Cost B/W(follow VM) | C22: 2 | D22: VM | E22: =300*0.8 -> 240 | F22: =C22*E22 -> 480 | G22: =F22*$E$9 -> 960 | H22: =G22/$G$5 -> #REF! | I22: =G22/$I$9 -> 1200 | J22: =I22/$E$9 -> 600
A23: INET | B23: IP Address(follow VM) | C23: 2 | D23: IP | E23: =80*0.8 -> 64 | F23: =C23*E23 -> 128 | G23: =F23*$E$9 -> 256 | H23: =G23/$G$5 -> #REF! | I23: =G23/$I$9 -> 320 | J23: =I23/$E$9 -> 160
A24: INET | B24: Monitoring& Alert(follow VM) | C24: 2 | D24: Vm | E24: =150*0.8 -> 120 | F24: =C24*E24 -> 240 | G24: =F24*$E$9 -> 480 | H24: =G24/$G$5 -> #REF! | I24: =G24/$I$9 -> 600 | J24: =I24/$E$9 -> 300
A25: INET | B25: Antivirus(follow VM) | C25: 2 | D25: Vm | E25: =150*0.8 -> 120 | F25: =C25*E25 -> 240 | G25: =F25*$E$9 -> 480 | H25: =G25/$G$5 -> #REF! | I25: =G25/$I$9 -> 600 | J25: =I25/$E$9 -> 300
A26: INET | B26: Operation Cost(follow VM) | C26: 2 | D26: Vm | E26: =200*0.8 -> 160 | F26: =C26*E26 -> 320 | G26: =F26*$E$9 -> 640 | H26: =G26/$G$5 -> #REF! | I26: =G26/$I$9 -> 800 | J26: =I26/$E$9 -> 400
A27: INET | B27: SQL License Std. /2 vcpu | D27: License | E27: =510*0.8 -> 408 | F27: =C27*E27 -> 0 | G27: =F27*$E$9 -> 0 | H27: =G27/$G$5 -> #REF! | I27: =G27/$I$9 -> 0 | J27: =I27/$E$9 -> 0
B28: Security By Project Team | C28: 0 | F28: =C28*E28 -> 0 | G28: =F28*$E$9 -> 0 | H28: =G28/$G$5 -> #REF! | I28: =G28/$I$9 -> 0 | J28: =I28/$E$9 -> 0
A29: INET | B29: Virtual Firewall Force point + VPN 10 Accounts + Policy 300 Policy | C29: 1 | D29: Unit | E29: =8000*0.8 -> 6400 | F29: =C29*E29 -> 6400 | G29: =F29*$E$9 -> 12800 | H29: =G29/$G$5 -> #REF! | I29: =G29/$I$9 -> 16000 | J29: =I29/$E$9 -> 8000
B30: Manage Service By Project Team | C30: 0 | F30: =C30*E30 -> 0 | G30: =F30*$E$9 -> 0 | H30: =G30/$G$5 -> #REF! | I30: =G30/$I$9 -> 0 | J30: =I30/$E$9 -> 0
A31: Project | B31: Manage Service (Monitoring) | C31: 2 | D31: Vm | E31: =1000*0.8 -> 800 | F31: =C31*E31 -> 1600 | G31: =F31*$E$9 -> 3200 | H31: =G31/$G$5 -> #REF! | I31: =G31/$I$9 -> 4000 | J31: =I31/$E$9 -> 2000
A32: Project | B32: DBA MYSQL for 1 VM (Advance Scope) | C32: 0 | D32: VM | E32: =15000*0.8 -> 12000 | F32: =C32*E32 -> 0 | G32: =F32*$E$9 -> 0 | H32: =G32/$G$5 -> #REF! | I32: =G32/$I$9 -> 0 | J32: =I32/$E$9 -> 0
B33: Add-On | E33: 0 | F33: =C33*E33 -> 0 | G33: =F33*$E$9 -> 0 | H33: =G33/$G$5 -> #REF! | I33: =G33/$I$9 -> 0 | J33: =I33/$E$9 -> 0
A34: Vendor | B34: Innitial setup c panel & support หลังงานติดตั้ง 24x7 | C34: 1 | D34: unit | F34: =C34*E34 -> 0 | G34: =F34*$E$9 -> 0 | H34: =G34/$G$5 -> #REF! | I34: =G34/$I$9 -> 0 | J34: =I34/$E$9 -> 0
B35: Grand Total | G35: =SUM(G11:G34) -> #REF! | H35: =G35/$G$5 -> #REF! | I35: =SUM(I11:I34) -> #REF! | J35: =SUM(J11:J34) -> #REF!
B36: Total Cost | C36: =E9 -> 2 | D36: Month | F36: =I35 -> #REF!
B37: Cost per Month | C37: 1 | D37: =D36 -> Month | F37: =F36/C36 -> #REF!
B38: Sale | F38: =F37*0.9 -> #REF!
B39: Sale Factor | F39: =F38/F37 -> #REF!
B41: Remark :
B42: throughput vFW เป็น estinmate
...

Sheet Diagram-99.90%
E1: เอกสารสนับสนุน (แบบฟอร์ม) | H1: หน่วยงาน : ส่วนงานบริหารต้นทุนองค์กร | L1: version 1.0 | O1: วันที่บังคับใช้ : 09/05/2016
E2: หัวข้อ : BOM (Bill of Material) Cost | I2: FM-BOM Cost | L2: ผู้อนุมัติ : | M2: หรรษา นวาระพรรณ | Q2: หน้า : 1/1
B3: Project Solution
B4: Project :
B5: Create by :
B6: Approved by :
B7: Version :
B8: Solution Diagram
G10: Capture figure diagram
G11: (ใส่รูปภาพที่ได้นำเสนอและตกลงร่วมกับลูกค้า)
B19: อธิบาย Solution [อ้างอิงตาม Diagram]

Sheet Cost Managed service
L12: 25000
L14: 15000
